Workbook

Sheet Statistics Data - Survey Result
A1: Years | B1: Months | C1: Age (months) | D1: Grade | E1: Driver License | F1: Leave Campus for Lunch | G1: Perception About Lunches | H1: Predicted | I1: Residual | V1: Min | W1: Q1 | X1: Med | Y1: Q3 | Z1: Max | AA1: IQR | AB1: Mean | AC1: SD | AD1: Range
A2: 16 | B2: 0 | C2: 192 | D2: 10 | E2: 0 | F2: 4 | G2: 9 | H2: =0.1046*E2+1.6306 -> 1.6306 | I2: =F2-H2 -> 2.3694 | U2: Driver License | V2: =MIN(E2:E104) -> 0 | W2: =QUARTILE(E2:E104, 1) -> 0 | X2: =MEDIAN(E2:E104) -> 6 | Y2: =QUARTILE(E2:E104,3) -> 16.5 | Z2: =MAX(E2:E104) -> 29 | AA2: =Y2-W2 -> 16.5 | AB2: =AVERAGE(E2:E104) -> 8.5436893 | AC2: =STDEV(E2:E104) -> 9.4046054 | AD2: =Z2-V2 -> 29
A3: 15 | B3: 11 | C3: 191 | D3: 10 | E3: 0 | F3: 0 | G3: 8 | H3: =0.1046*E3+1.6306 -> 1.6306 | I3: =F3-H3 -> -1.6306 | U3: Leave Campus for Lunch | V3: =MIN(F2:F104) -> 0 | W3: =QUARTILE(F2:F104, 1) -> 0 | X3: =MEDIAN(F2:F104) -> 3 | Y3: =QUARTILE(F2:F104,3) -> 5 | Z3: =MAX(F2:F104) -> 5 | AA3: =Y3-W3 -> 5 | AB3: =AVERAGE(F2:F104) -> 2.5242718 | AC3: =STDEV(F2:F104) -> 2.0428962 | AD3: =Z3-V3 -> 5
A4: 16 | B4: 1 | C4: 193 | D4: 10 | E4: 0 | F4: 0 | G4: 9 | H4: =0.1046*E4+1.6306 -> 1.6306 | I4: =F4-H4 -> -1.6306
A5: 15 | B5: 8 | C5: 188 | D5: 10 | E5: 0 | F5: 1 | G5: 8 | H5: =0.1046*E5+1.6306 -> 1.6306 | I5: =F5-H5 -> -0.6306
A6: 16 | B6: 1 | C6: 193 | D6: 10 | E6: 0 | F6: 0 | G6: 8 | H6: =0.1046*E6+1.6306 -> 1.6306 | I6: =F6-H6 -> -1.6306
A7: 15 | B7: 10 | C7: 190 | D7: 10 | E7: 7 | F7: 0 | G7: 9 | H7: =0.1046*E7+1.6306 -> 2.3628 | I7: =F7-H7 -> -2.3628
A8: 15 | B8: 3 | C8: 183 | D8: 10 | E8: 0 | F8: 3 | G8: 9 | H8: =0.1046*E8+1.6306 -> 1.6306 | I8: =F8-H8 -> 1.3694
A9: 15 | B9: 10 | C9: 190 | D9: 10 | E9: 0 | F9: 1 | G9: 10 | H9: =0.1046*E9+1.6306 -> 1.6306 | I9: =F9-H9 -> -0.6306
A10: 16 | B10: 2 | C10: 194 | D10: 10 | E10: 0 | F10: 0 | G10: 4 | H10: =0.1046*E10+1.6306 -> 1.6306 | I10: =F10-H10 -> -1.6306
A11: 15 | B11: 6 | C11: 186 | D11: 10 | E11: 0 | F11: 2 | G11: 10 | H11: =0.1046*E11+1.6306 -> 1.6306 | I11: =F11-H11 -> 0.3694
A12: 16 | B12: 1 | C12: 193 | D12: 10 | E12: 0 | F12: 3 | G12: 10 | H12: =0.1046*E12+1.6306 -> 1.6306 | I12: =F12-H12 -> 1.3694
A13: 15 | B13: 5 | C13: 185 | D13: 10 | E13: 0 | F13: 0 | G13: 7 | H13: =0.1046*E13+1.6306 -> 1.6306 | I13: =F13-H13 -> -1.6306
A14: 15 | B14: 4 | C14: 184 | D14: 10 | E14: 0 | F14: 0 | G14: 8 | H14: =0.1046*E14+1.6306 -> 1.6306 | I14: =F14-H14 -> -1.6306
A15: 15 | B15: 8 | C15: 188 | D15: 10 | E15: 0 | F15: 2 | G15: 7 | H15: =0.1046*E15+1.6306 -> 1.6306 | I15: =F15-H15 -> 0.3694
... A19: 16 | B19: 9 | C19: 201 | D19: 11 | E19: 6 | F19: 5 | G19: 5 | H19: =0.1046*E19+1.6306 -> 2.2582 | I19: =F19-H19 -> 2.7418
A20: 16 | B20: 9 | C20: 201 | D20: 11 | E20: 8 | F20: 3 | G20: 3 | H20: =0.1046*E20+1.6306 -> 2.4674 | I20: =F20-H20 -> 0.5326 | K20: Well the equation that I get from calculator is different from what excel says... I'm not really sure what to do I probably just entered my data wrong
A21: 17 | B21: 2 | C21: 206 | D21: 11 | E21: 14 | F21: 4 | G21: 3 | H21: =0.1046*E21+1.6306 -> 3.095 | I21: =F21-H21 -> 0.905
A22: 16 | B22: 9 | C22: 201 | D22: 11 | E22: 9 | F22: 1 | G22: 10 | H22: =0.1046*E22+1.6306 -> 2.572 | I22: =F22-H22 -> -1.572 | K22: excel: y = 0.1046x + 1.6306, R² = 0.2319, r=.4816
A23: 17 | B23: 9 | C23: 213 | D23: 12 | E23: 21 | F23: 5 | G23: 5 | H23: =0.1046*E23+1.6306 -> 3.8272 | I23: =F23-H23 -> 1.1728 | K23: also i'm really not really convinced that there's 103 points on that graph
A24: 17 | B24: 10 | C24: 214 | D24: 12 | E24: 16 | F24: 1 | G24: 2 | H24: =0.1046*E24+1.6306 -> 3.3042 | I24: =F24-H24 -> -2.3042 | K24: oh that's because some of the points are the same, so they will be on each other
A25: 17 | B25: 11 | C25: 215 | D25: 12 | E25: 15 | F25: 1 | G25: 10 | H25: =0.1046*E25+1.6306 -> 3.1996 | I25: =F25-H25 -> -2.1996 | K25: just go with excel i guess
A26: 17 | B26: 8 | C26: 212 | D26: 12 | E26: 18 | F26: 5 | G26: 1 | H26: =0.1046*E26+1.6306 -> 3.5134 | I26: =F26-H26 -> 1.4866
A27: 17 | B27: 4 | C27: 208 | D27: 12 | E27: 11 | F27: 1 | G27: 3 | H27: =0.1046*E27+1.6306 -> 2.7812 | I27: =F27-H27 -> -1.7812
A28: 17 | B28: 11 | C28: 215 | D28: 12 | E28: 22 | F28: 5 | G28: 4 | H28: =0.1046*E28+1.6306 -> 3.9318 | I28: =F28-H28 -> 1.0682
A29: 18 | B29: 2 | C29: 218 | D29: 12 | E29: 26 | F29: 1 | G29: 10 | H29: =0.1046*E29+1.6306 -> 4.3502 | I29: =F29-H29 -> -3.3502
A30: 17 | B30: 5 | C30: 209 | D30: 12 | E30: 27 | F30: 0 | G30: 10 | H30: =0.1046*E30+1.6306 -> 4.4548 | I30: =F30-H30 -> -4.4548
A31: 17 | B31: 1 | C31: 205 | D31: 12 | E31: 0 | F31: 3 | G31: 6 | H31: =0.1046*E31+1.6306 -> 1.6306 | I31: =F31-H31 -> 1.3694
A32: 18 | B32: 2 | C32: 218 | D32: 12 | E32: 27 | F32: 5 | G32: 4 | H32: =0.1046*E32+1.6306 -> 4.4548 | I32: =F32-H32 -> 0.5452
A33: 17 | B33: 8 | C33: 212 | D33: 12 | E33: 18 | F33: 5 | G33: 8 | H33: =0.1046*E33+1.6306 -> 3.5134 | I33: =F33-H33 -> 1.4866
A34: 17 | B34: 5 | C34: 209 | D34: 12 | E34: 0 | F34: 2 | G34: 1 | H34: =0.1046*E34+1.6306 -> 1.6306 | I34: =F34-H34 -> 0.3694
A35: 17 | B35: 4 | C35: 208 | D35: 12 | E35: 0 | F35: 3 | G35: 10 | H35: =0.1046*E35+1.6306 -> 1.6306 | I35: =F35-H35 -> 1.3694
A36: 17 | B36: 9 | C36: 213 | D36: 12 | E36: 15 | F36: 0 | G36: 10 | H36: =0.1046*E36+1.6306 -> 3.1996 | I36: =F36-H36 -> -3.1996
A37: 18 | B37: 3 | C37: 219 | D37: 12 | E37: 12 | F37: 3 | G37: 5 | H37: =0.1046*E37+1.6306 -> 2.8858 | I37: =F37-H37 -> 0.1142 | U37: Oh nice
A38: 18 | B38: 2 | C38: 218 | D38: 12 | E38: 24 | F38: 5 | G38: 10 | H38: =0.1046*E38+1.6306 -> 4.141 | I38: =F38-H38 -> 0.859
A39: 17 | B39: 19 | C39: 223 | D39: 12 | E39: 21 | F39: 5 | G39: 5 | H39: =0.1046*E39+1.6306 -> 3.8272 | I39: =F39-H39 -> 1.1728
A40: 18 | B40: 1 | C40: 217 | D40: 12 | E40: 20 | F40: 5 | G40: 4 | H40: =0.1046*E40+1.6306 -> 3.7226 | I40: =F40-H40 -> 1.2774
A41: 17 | B41: 6 | C41: 210 | D41: 12 | E41: 18 | F41: 5 | G41: 1 | H41: =0.1046*E41+1.6306 -> 3.5134 | I41: =F41-H41 -> 1.4866
A42: 17 | B42: 7 | C42: 211 | D42: 12 | E42: 19 | F42: 5 | G42: 1 | H42: =0.1046*E42+1.6306 -> 3.618 | I42: =F42-H42 -> 1.382
A43: 18 | B43: 2 | C43: 218 | D43: 12 | E43: 26 | F43: 5 | G43: 7 | H43: =0.1046*E43+1.6306 -> 4.3502 | I43: =F43-H43 -> 0.6498
...

Sheet Sheet1
A1: Driver License | B1: Leave Campus for Lunch | D1: DL1 | E1: Lunch1 | F1: DL3 | G1: Lunch3 | H1: DL5 | I1: Lunch5 | L1: Min | M1: Q1 | N1: Med | O1: Q3 | P1: Max
A2: 0 | B2: 0 | D2: 0 | E2: 0 | F2: 0 | G2: 2 | H2: 0 | I2: 4 | L2: =MIN(D2:D43) -> 0 | M2: =QUARTILE(D2:D43,1) -> 0 | N2: =MEDIAN(D2:D43) -> 0 | O2: =N6
A3: 0 | B3: 0 | D3: 0 | E3: 0 | F3: 0 | G3: 2 | H3: 14 | I3: 4
A4: 0 | B4: 0 | D4: 0 | E4: 0 | F4: 0 | G4: 2 | H4: 0 | I4: 4
A5: 7 | B5: 0 | D5: 7 | E5: 0 | F5: 6 | G5: 2 | H5: 0 | I5: 4
A6: 0 | B6: 0 | D6: 0 | E6: 0 | F6: 0 | G6: 2 | H6: 0 | I6: 4
A7: 0 | B7: 0 | D7: 0 | E7: 0 | F7: 0 | G7: 2 | H7: 14 | I7: 5
A8: 0 | B8: 0 | D8: 0 | E8: 0 | F8: 0 | G8: 2 | H8: 15 | I8: 5
A9: 27 | B9: 0 | D9: 27 | E9: 0 | F9: 0 | G9: 2 | H9: 6 | I9: 5
A10: 15 | B10: 0 | D10: 15 | E10: 0 | F10: 0 | G10: 2 | H10: 21 | I10: 5
A11: 0 | B11: 0 | D11: 0 | E11: 0 | F11: 0 | G11: 3 | H11: 18 | I11: 5
A12: 0 | B12: 0 | D12: 0 | E12: 0 | F12: 0 | G12: 3 | H12: 22 | I12: 5
A13: 0 | B13: 0 | D13: 0 | E13: 0 | F13: 11 | G13: 3 | H13: 27 | I13: 5
A14: 7 | B14: 0 | D14: 7 | E14: 0 | F14: 8 | G14: 3 | H14: 18 | I14: 5
... A24: 0 | B24: 0 | D24: 0 | E24: 0 | F24: 0 | G24: 3 | H24: 18 | I24: 5
A25: 0 | B25: 0 | D25: 0 | E25: 0 | H25: 16 | I25: 5
A26: 0 | B26: 0 | D26: 0 | E26: 0 | H26: 18 | I26: 5
A27: 1 | B27: 0 | D27: 1 | E27: 0 | H27: 23 | I27: 5
A28: 0 | B28: 0 | D28: 0 | E28: 0 | H28: 1 | I28: 5
A29: 0 | B29: 1 | D29: 0 | E29: 1 | H29: 16 | I29: 5
A30: 0 | B30: 1 | D30: 0 | E30: 1 | H30: 18 | I30: 5
A31: 9 | B31: 1 | D31: 9 | E31: 1 | H31: 25 | I31: 5
A32: 16 | B32: 1 | D32: 16 | E32: 1 | H32: 17 | I32: 5
A33: 15 | B33: 1 | D33: 15 | E33: 1 | H33: 11 | I33: 5
A34: 11 | B34: 1 | D34: 11 | E34: 1 | H34: 21 | I34: 5
A35: 26 | B35: 1 | D35: 26 | E35: 1 | H35: 19 | I35: 5
A36: 8 | B36: 1 | D36: 8 | E36: 1 | H36: 12 | I36: 5
... A39: 1 | B39: 1 | D39: 1 | E39: 1 | H39: 0 | I39: 5
A40: 27 | B40: 1 | D40: 27 | E40: 1
A41: 0 | B41: 1 | D41: 0 | E41: 1
A42: 0 | B42: 1 | D42: 0 | E42: 1
A43: 0 | B43: 1 | D43: 0 | E43: 1
A44: 0 | B44: 2
A45: 0 | B45: 2
A46: 0 | B46: 2
A47: 6 | B47: 2
A48: 0 | B48: 2
A49: 0 | B49: 2
A50: 0 | B50: 2
A51: 0 | B51: 2
...

Sheet Driver License Graphs
A1: Driver License | B1: Upper Limits | C1: Labels | E1: Bin | F1: Frequency | Q1: DL Sorted | S1: Stem | T1: Leaf | U1: Leaf Position
A2: 0 | B2: 0 | C2: 0 | E2: 0 | F2: 45 | Q2: {=SORT(A2:A104)} -> 0 | S2: =VALUE(LEFT(Q2,1)) -> 0 | T2: =VALUE(RIGHT(Q2,1)) -> 0 | U2: =COUNTIF($S$2:S2,S2) -> 1
A3: 0 | B3: 6 | C3: 1-6 | E3: 6 | F3: 8 | Q3: 0 | S3: =VALUE(LEFT(Q3,1)) -> 0 | T3: =VALUE(RIGHT(Q3,1)) -> 0 | U3: =COUNTIF($S$2:S3,S3) -> 2
A4: 0 | B4: 12 | C4: 7-12 | E4: 12 | F4: 14 | Q4: 0 | S4: =VALUE(LEFT(Q4,1)) -> 0 | T4: =VALUE(RIGHT(Q4,1)) -> 0 | U4: =COUNTIF($S$2:S4,S4) -> 3
A5: 0 | B5: 18 | C5: 13-18 | E5: 18 | F5: 18 | Q5: 0 | S5: =VALUE(LEFT(Q5,1)) -> 0 | T5: =VALUE(RIGHT(Q5,1)) -> 0 | U5: =COUNTIF($S$2:S5,S5) -> 4
A6: 0 | B6: 24 | C6: 19-24 | E6: 24 | F6: 10 | Q6: 0 | S6: =VALUE(LEFT(Q6,1)) -> 0 | T6: =VALUE(RIGHT(Q6,1)) -> 0 | U6: =COUNTIF($S$2:S6,S6) -> 5
A7: 7 | B7: 30 | C7: 25-30 | E7: 30 | F7: 8 | Q7: 0 | S7: =VALUE(LEFT(Q7,1)) -> 0 | T7: =VALUE(RIGHT(Q7,1)) -> 0 | U7: =COUNTIF($S$2:S7,S7) -> 6
A8: 0 | E8: More | F8: 0 | Q8: 0 | S8: =VALUE(LEFT(Q8,1)) -> 0 | T8: =VALUE(RIGHT(Q8,1)) -> 0 | U8: =COUNTIF($S$2:S8,S8) -> 7
A9: 0 | Q9: 0 | S9: =VALUE(LEFT(Q9,1)) -> 0 | T9: =VALUE(RIGHT(Q9,1)) -> 0 | U9: =COUNTIF($S$2:S9,S9) -> 8
A10: 0 | Q10: 0 | S10: =VALUE(LEFT(Q10,1)) -> 0 | T10: =VALUE(RIGHT(Q10,1)) -> 0 | U10: =COUNTIF($S$2:S10,S10) -> 9
A11: 0 | Q11: 0 | S11: =VALUE(LEFT(Q11,1)) -> 0 | T11: =VALUE(RIGHT(Q11,1)) -> 0 | U11: =COUNTIF($S$2:S11,S11) -> 10
A12: 0 | Q12: 0 | S12: =VALUE(LEFT(Q12,1)) -> 0 | T12: =VALUE(RIGHT(Q12,1)) -> 0 | U12: =COUNTIF($S$2:S12,S12) -> 11
A13: 0 | Q13: 0 | S13: =VALUE(LEFT(Q13,1)) -> 0 | T13: =VALUE(RIGHT(Q13,1)) -> 0 | U13: =COUNTIF($S$2:S13,S13) -> 12
A14: 0 | Q14: 0 | S14: =VALUE(LEFT(Q14,1)) -> 0 | T14: =VALUE(RIGHT(Q14,1)) -> 0 | U14: =COUNTIF($S$2:S14,S14) -> 13
A15: 0 | Q15: 0 | S15: =VALUE(LEFT(Q15,1)) -> 0 | T15: =VALUE(RIGHT(Q15,1)) -> 0 | U15: =COUNTIF($S$2:S15,S15) -> 14
A16: 14 | Q16: 0 | S16: =VALUE(LEFT(Q16,1)) -> 0 | T16: =VALUE(RIGHT(Q16,1)) -> 0 | U16: =COUNTIF($S$2:S16,S16) -> 15
A17: 11 | Q17: 0 | S17: =VALUE(LEFT(Q17,1)) -> 0 | T17: =VALUE(RIGHT(Q17,1)) -> 0 | U17: =COUNTIF($S$2:S17,S17) -> 16
A18: 15 | Q18: 0 | S18: =VALUE(LEFT(Q18,1)) -> 0 | T18: =VALUE(RIGHT(Q18,1)) -> 0 | U18: =COUNTIF($S$2:S18,S18) -> 17
A19: 6 | Q19: 0 | S19: =VALUE(LEFT(Q19,1)) -> 0 | T19: =VALUE(RIGHT(Q19,1)) -> 0 | U19: =COUNTIF($S$2:S19,S19) -> 18
A20: 8 | Q20: 0 | S20: =VALUE(LEFT(Q20,1)) -> 0 | T20: =VALUE(RIGHT(Q20,1)) -> 0 | U20: =COUNTIF($S$2:S20,S20) -> 19
... A46: 10 | Q46: 0 | S46: =VALUE(LEFT(Q46,1)) -> 0 | T46: =VALUE(RIGHT(Q46,1)) -> 0 | U46: =COUNTIF($S$2:S46,S46) -> 45
A47: 0 | Q47: 1 | S47: 0 | T47: =VALUE(RIGHT(Q47,1)) -> 1 | U47: =COUNTIF($S$2:S47,S47) -> 46
A48: 0 | Q48: 1 | S48: 0 | T48: =VALUE(RIGHT(Q48,1)) -> 1 | U48: =COUNTIF($S$2:S48,S48) -> 47
A49: 6 | Q49: 1 | S49: 0 | T49: =VALUE(RIGHT(Q49,1)) -> 1 | U49: =COUNTIF($S$2:S49,S49) -> 48
A50: 0 | Q50: 3 | S50: 0 | T50: =VALUE(RIGHT(Q50,1)) -> 3 | U50: =COUNTIF($S$2:S50,S50) -> 49
A51: 0 | Q51: 4 | S51: 0 | T51: =VALUE(RIGHT(Q51,1)) -> 4 | U51: =COUNTIF($S$2:S51,S51) -> 50
A52: 0 | Q52: 4 | S52: 0 | T52: =VALUE(RIGHT(Q52,1)) -> 4 | U52: =COUNTIF($S$2:S52,S52) -> 51
A53: 0 | Q53: 6 | S53: 0 | T53: =VALUE(RIGHT(Q53,1)) -> 6 | U53: =COUNTIF($S$2:S53,S53) -> 52
A54: 1 | Q54: 6 | S54: 0 | T54: =VALUE(RIGHT(Q54,1)) -> 6 | U54: =COUNTIF($S$2:S54,S54) -> 53
A55: 8 | Q55: 7 | S55: 0 | T55: =VALUE(RIGHT(Q55,1)) -> 7 | U55: =COUNTIF($S$2:S55,S55) -> 54
A56: 15 | Q56: 7 | S56: 0 | T56: =VALUE(RIGHT(Q56,1)) -> 7 | U56: =COUNTIF($S$2:S56,S56) -> 55
A57: 18 | Q57: 8 | S57: 0 | T57: =VALUE(RIGHT(Q57,1)) -> 8 | U57: =COUNTIF($S$2:S57,S57) -> 56
A58: 16 | Q58: 8 | S58: 0 | T58: =VALUE(RIGHT(Q58,1)) -> 8 | U58: =COUNTIF($S$2:S58,S58) -> 57
... A61: 23 | Q61: 9 | S61: 0 | T61: =VALUE(RIGHT(Q61,1)) -> 9 | U61: =COUNTIF($S$2:S61,S61) -> 60
A62: 1 | Q62: 10 | S62: =VALUE(LEFT(Q62,1)) -> 1 | T62: =VALUE(RIGHT(Q62,1)) -> 0 | U62: =COUNTIF($S$2:S62,S62) -> 1
A63: 7 | Q63: 11 | S63: =VALUE(LEFT(Q63,1)) -> 1 | T63: =VALUE(RIGHT(Q63,1)) -> 1 | U63: =COUNTIF($S$2:S63,S63) -> 2
A64: 16 | Q64: 11 | S64: =VALUE(LEFT(Q64,1)) -> 1 | T64: =VALUE(RIGHT(Q64,1)) -> 1 | U64: =COUNTIF($S$2:S64,S64) -> 3
A65: 18 | Q65: 11 | S65: =VALUE(LEFT(Q65,1)) -> 1 | T65: =VALUE(RIGHT(Q65,1)) -> 1 | U65: =COUNTIF($S$2:S65,S65) -> 4
A66: 25 | Q66: 12 | S66: =VALUE(LEFT(Q66,1)) -> 1 | T66: =VALUE(RIGHT(Q66,1)) -> 2 | U66: =COUNTIF($S$2:S66,S66) -> 5
A67: 17 | Q67: 12 | S67: =VALUE(LEFT(Q67,1)) -> 1 | T67: =VALUE(RIGHT(Q67,1)) -> 2 | U67: =COUNTIF($S$2:S67,S67) -> 6
...

Sheet Lunch Graphs
A1: Leave Campus for Lunch | B1: Upper Limits | D1: Bin | E1: Frequency
A2: 4 | B2: 0 | D2: 0 | E2: 27
A3: 0 | B3: 1 | D3: 1 | E3: 15
A4: 0 | B4: 2 | D4: 2 | E4: 9
A5: 1 | B5: 3 | D5: 3 | E5: 14
A6: 0 | B6: 4 | D6: 4 | E6: 5
A7: 0 | B7: 5 | D7: 5 | E7: 33
A8: 3 | D8: More | E8: 0
A9: 1
A10: 0
A11: 2
A12: 3
A13: 0
A14: 0
A15: 2
A16: 5
A17: 3
A18: 5
A19: 5 | D19: Bin | E19: Frequency | F19: Cumulative %
A20: 3 | D20: 0 | E20: 27 | F20: 0.26213592
A21: 4 | D21: 1 | E21: 15 | F21: 0.40776699
A22: 1 | D22: 2 | E22: 9 | F22: 0.49514563 | G22: Frequency Table
A23: 5 | D23: 3 | E23: 14 | F23: 0.63106796 | G23: Leave Campus for Lunch | H23: Frequency | I23: Cumulative Frequency | J23: Relative Frequency | K23: Cumulative Relative Frequency
A24: 1 | D24: 4 | E24: 5 | F24: 0.67961165 | G24: 0 | H24: 27 | I24: 27 | J24: =H24/'Lunch Graphs'!$H$30 -> 0.26213592 | K24: =I24/'Lunch Graphs'!$H$30 -> 0.26213592
A25: 1 | D25: 5 | E25: 33 | F25: 1 | G25: 1 | H25: 15 | I25: =I24+H25 -> 42 | J25: =H25/'Lunch Graphs'!$H$30 -> 0.14563107 | K25: =I25/'Lunch Graphs'!$H$30 -> 0.40776699
A26: 5 | D26: More | E26: 0 | F26: 1 | G26: 2 | H26: 9 | I26: =I25+H26 -> 51 | J26: =H26/'Lunch Graphs'!$H$30 -> 0.087378641 | K26: =I26/'Lunch Graphs'!$H$30 -> 0.49514563
A27: 1 | G27: 3 | H27: 14 | I27: =I26+H27 -> 65 | J27: =H27/'Lunch Graphs'!$H$30 -> 0.13592233 | K27: =I27/'Lunch Graphs'!$H$30 -> 0.63106796
A28: 5 | G28: 4 | H28: 5 | I28: =I27+H28 -> 70 | J28: =H28/'Lunch Graphs'!$H$30 -> 0.048543689 | K28: =I28/'Lunch Graphs'!$H$30 -> 0.67961165
A29: 1 | G29: 5 | H29: 33 | I29: =I28+H29 -> 103 | J29: =H29/'Lunch Graphs'!$H$30 -> 0.32038835 | K29: =I29/'Lunch Graphs'!$H$30 -> 1
A30: 0 | G30: Total | H30: 103 | I30: 103 | J30: 1 | K30: 100.00%
A31: 3
A32: 5
A33: 5
A34: 2
A35: 3
A36: 0
A37: 3
A38: 5
A39: 5
A40: 5
...
